[2024-05-21T03:37:43.063+0000] {taskinstance.py:1979} INFO - Dependencies all met for dep_context=non-requeueable deps ti=<TaskInstance: data_merging_etl_dag.extract_api_data scheduled__2024-05-20T00:00:00+00:00 [queued]>
[2024-05-21T03:37:43.080+0000] {taskinstance.py:1979} INFO - Dependencies all met for dep_context=requeueable deps ti=<TaskInstance: data_merging_etl_dag.extract_api_data scheduled__2024-05-20T00:00:00+00:00 [queued]>
[2024-05-21T03:37:43.081+0000] {taskinstance.py:2193} INFO - Starting attempt 1 of 2
[2024-05-21T03:37:43.094+0000] {taskinstance.py:2217} INFO - Executing <Task(_PythonDecoratedOperator): extract_api_data> on 2024-05-20 00:00:00+00:00
[2024-05-21T03:37:43.103+0000] {standard_task_runner.py:60} INFO - Started process 90 to run task
[2024-05-21T03:37:43.123+0000] {standard_task_runner.py:87} INFO - Running: ['***', 'tasks', 'run', 'data_merging_etl_dag', 'extract_api_data', 'scheduled__2024-05-20T00:00:00+00:00', '--job-id', '3', '--raw', '--subdir', 'DAGS_FOLDER/dag_decorators.py', '--cfg-path', '/tmp/tmpo697ev_0']
[2024-05-21T03:37:43.126+0000] {standard_task_runner.py:88} INFO - Job 3: Subtask extract_api_data
[2024-05-21T03:37:43.452+0000] {task_command.py:423} INFO - Running <TaskInstance: data_merging_etl_dag.extract_api_data scheduled__2024-05-20T00:00:00+00:00 [running]> on host d75b385b4659
[2024-05-21T03:37:43.622+0000] {taskinstance.py:2513} INFO - Exporting env vars: AIRFLOW_CTX_DAG_EMAIL='***@example.com' AIRFLOW_CTX_DAG_OWNER='***' AIRFLOW_CTX_DAG_ID='data_merging_etl_dag' AIRFLOW_CTX_TASK_ID='extract_api_data' AIRFLOW_CTX_EXECUTION_DATE='2024-05-20T00:00:00+00:00' AIRFLOW_CTX_TRY_NUMBER='1' AIRFLOW_CTX_DAG_RUN_ID='scheduled__2024-05-20T00:00:00+00:00'
[2024-05-21T03:37:43.648+0000] {etl.py:39} ERROR - Failed to load [Errno 2] No such file or directory: '../data/api_data_1.csv'
[2024-05-21T03:37:43.660+0000] {taskinstance.py:2731} ERROR - Task failed with exception
Traceback (most recent call last):
  File "/home/airflow/.local/lib/python3.9/site-packages/airflow/models/taskinstance.py", line 444, in _execute_task
    result = _execute_callable(context=context, **execute_callable_kwargs)
  File "/home/airflow/.local/lib/python3.9/site-packages/airflow/models/taskinstance.py", line 414, in _execute_callable
    return execute_callable(context=context, **execute_callable_kwargs)
  File "/home/airflow/.local/lib/python3.9/site-packages/airflow/decorators/base.py", line 241, in execute
    return_value = super().execute(context)
  File "/home/airflow/.local/lib/python3.9/site-packages/airflow/operators/python.py", line 200, in execute
    return_value = self.execute_callable()
  File "/home/airflow/.local/lib/python3.9/site-packages/airflow/operators/python.py", line 217, in execute_callable
    return self.python_callable(*self.op_args, **self.op_kwargs)
  File "/opt/airflow/dags/dag_decorators.py", line 30, in extract_api_data
    return etl.extract_api_data()
  File "/opt/airflow/dags/etl.py", line 36, in extract_api_data
    df = pd.read_csv(file)
  File "/home/airflow/.local/lib/python3.9/site-packages/pandas/io/parsers/readers.py", line 948, in read_csv
    return _read(filepath_or_buffer, kwds)
  File "/home/airflow/.local/lib/python3.9/site-packages/pandas/io/parsers/readers.py", line 611, in _read
    parser = TextFileReader(filepath_or_buffer, **kwds)
  File "/home/airflow/.local/lib/python3.9/site-packages/pandas/io/parsers/readers.py", line 1448, in __init__
    self._engine = self._make_engine(f, self.engine)
  File "/home/airflow/.local/lib/python3.9/site-packages/pandas/io/parsers/readers.py", line 1705, in _make_engine
    self.handles = get_handle(
  File "/home/airflow/.local/lib/python3.9/site-packages/pandas/io/common.py", line 863, in get_handle
    handle = open(
FileNotFoundError: [Errno 2] No such file or directory: '../data/api_data_1.csv'
[2024-05-21T03:37:43.679+0000] {taskinstance.py:1149} INFO - Marking task as UP_FOR_RETRY. dag_id=data_merging_etl_dag, task_id=extract_api_data, execution_date=20240520T000000, start_date=20240521T033743, end_date=20240521T033743
[2024-05-21T03:37:43.692+0000] {standard_task_runner.py:107} ERROR - Failed to execute job 3 for task extract_api_data ([Errno 2] No such file or directory: '../data/api_data_1.csv'; 90)
[2024-05-21T03:37:43.731+0000] {local_task_job_runner.py:234} INFO - Task exited with return code 1
[2024-05-21T03:37:43.757+0000] {taskinstance.py:3312} INFO - 0 downstream tasks scheduled from follow-on schedule check
