[2024-05-21T05:50:11.946+0000] {scheduler_job_runner.py:1574} WARNING - Marking task instance <TaskInstance: data_merging_etl_dag.extract_metacritic_data scheduled__2024-05-20T00:00:00+00:00 [queued]> stuck in queued as failed. If the task instance has available retries, it will be retried.
[2024-05-21T05:50:12.254+0000] {scheduler_job_runner.py:780} ERROR - Executor reports task instance <TaskInstance: data_merging_etl_dag.extract_metacritic_data scheduled__2024-05-20T00:00:00+00:00 [queued]> finished (failed) although the task says it's queued. (Info: None) Was the task killed externally?
